Workbook

Sheet COMPOSIÇÃO DE CUSTOS
A1: ITENS | B1: DESCRIÇÃO | C1: UNIDADE MONETÁRIA | D1: VALOR ITEM | E1: VALOR TOTAL DO ITEM
A2: 1.0 | B2: DESPESAS
A3: 1.1 | B3: Tarifas e Serviços
B4: Energia Elétrica | C4: R$ | D4: 170
B5: IPTU (MENSAL) | C5: R$ | D5: 70
B6: TCR (MENSAL) | C6: R$ | D6: 20
B7: Telefone | C7: R$ | D7: 150
B8: Conexão de Dados | C8: R$ | D8: 50
B9: Subtotal (a) | C9: R$ | E9: =SUM(D4:D8) -> 460
A11: 1.2 | B11: Mão-de-Obra Administrativa
B12: Salário de Secretária/Digitadora | C12: R$ | D12: 1000
B13: Salário de auxiliar Técnico | C13: R$ | D13: 1100
B14: Faxineira (diarista) | C14: R$ | D14: 300
B15: Leis Sociais (85%) sobre o total da mão de obra | C15: R$ | D15: =SUM(D12:D14)*85% -> 2040
B16: Subtotal (b) | C16: R$ | E16: =SUM(D12:D15) -> 4440
A18: 1.3 | B18: Despesas de Escritório
B19: Aluguel/Condomínio | C19: R$ | D19: 1800
B20: Material de Escritório | C20: R$ | D20: 300
B21: Despesas de manutenção | C21: R$ | D21: 150
B22: Contador | C22: R$ | D22: 880
B23: Subtotal (c) | C23: R$ | E23: 3130
A25: 1.4 | B25: Transporte
B26: Locação de Veiculo pequeno (80%) | C26: R$ | D26: 1728
B27: Combustivel | C27: R$ | D27: 800
B28: Subtotal (d) | C28: R$ | E28: =SUM(D26:D27) -> 2528
A30: 1.5 | B30: Depresiação de ativo Imobilizado
B31: Móveis | C31: R$ | D31: 12000
B32: Equipementos de Informática, máquinas fotográficas, GPS, Software | C32: R$ | D32: 35000
B33: Ativos Imobilizado | C33: R$ | D33: 15500
B34: Depreciação móveis (80% em 10 anos) | C34: R$ | D34: 80
B35: Depreciação de outros equipementos (100% em 10 anos) | C35: R$ | D35: 29.17
B36: Subtotal (e) | C36: R$ | E36: 109.17
A38: 1.6 | B38: Custos Financeiros
B39: CF=1,5% x ativo imobilizado
B40: CF=0,015 x ativo imobilizado | C40: R$ | D40: 232.5
B41: CF mensal (Subtotal -f) | C41: R$ | E41: =D40 -> 232.5
A43: 2.0 | B43: Remuneração
A44: 2.1 | B44: Remuneração Mensal | C44: R$ | D44: 14000
B45: 13º Salário = (1/12)=8,33% da remuneração mensal | C45: R$ | D45: =D44*8.333% -> 1166.62
B46: Férias=(1/11)=9,09 % da remuneração mensal | C46: R$ | D46: =D44*9.09% -> 1272.6
...

Sheet RESUMO
A1: ITENS | B1: DESCRIÇÃO | C1: UNIDADE MONETÁRIA | D1: VALOR ITEM | E1: VALOR TOTAL DO ITEM
A2: 3.0 | B2: RESUMO
A3: 3.1 | B3: Despesas
B4: Tarifas e Serviços (subtotal -a ) | C4: R$ | D4: ='COMPOSIÇÃO DE CUSTOS'!E9 -> 460
B5: Mão-de-obra administrativa (Subtotal - b) | C5: R$ | D5: ='COMPOSIÇÃO DE CUSTOS'!E16 -> 4440
B6: Despesas de escritório (subtotal - c) | C6: R$ | D6: ='COMPOSIÇÃO DE CUSTOS'!E23 -> 3130
B7: Transporte (subtotal - d) | C7: R$ | D7: ='COMPOSIÇÃO DE CUSTOS'!E28 -> 2528
B8: Depreciação do Ativo Imobilizado (subtotal - e) | C8: R$ | D8: ='COMPOSIÇÃO DE CUSTOS'!E36 -> 109.17
B9: Custos Financeiros (subtotal - f) | C9: R$ | D9: ='COMPOSIÇÃO DE CUSTOS'!E41 -> 232.5
B10: Subtotal (h) | C10: R$ | E10: =SUM(D4:D9) -> 10899.67
B11: Reposição de IR s/ despesas (37,9%) | C11: R$ | D11: =E10*37.9% -> 4130.9749
B12: TOTAL 1 | C12: R$ | E12: =E10+D11 -> 15030.645
A13: 3.2 | B13: Remuneração | C13: R$
B14: Remuneração Mensal (Subtotal - g) | C14: R$ | D14: ='COMPOSIÇÃO DE CUSTOS'!E48 -> 17139.22
B15: TOTAL 2 | C15: R$ | E15: =D14 -> 17139.22
A16: 4.0 | B16: VALOR DA HORA TÉCNICA | C16: R$
B17: Parcela relativa às despesas | C17: R$
B18: VHT1= TOTAL 1/160 | C18: R$ | E18: =E12/160 -> 93.941531
A19: 4.2 | B19: Parcela relativa à remuneração profissional | C19: R$
B20: VHT2= TOTAL 2/160 | C20: R$ | E20: =E15/160 -> 107.12013
A21: 4.3 | B21: TOTAL (Valor da Hora Técnica) | C21: R$
B22: VHT = VHT1 + VHT 2 | C22: R$ | E22: =E18+E20 -> 201.06166
B23: Valor da Hora técnica adotado é de R$ 200,00 (duzentos reais) | C23: R$
