Workbook
Name Excel_BuiltIn_Print_Area_4: 'Gol 1_0 flex'!$C$1:$E$61

Sheet Planilha Orçamentária
A1: RAFAEL & CIA.
A4: OBJETO: CERTIFICAÇÃO E ATUALIZAÇÃO CADASTRAL POR GEORREFERENCIAMENTO
A5: LOCALIZAÇÃO: URUÇUBA, LIMOEIRO - PE
A6: DATA: JUNHO/2019
A8: PLANILHA ORÇAMENTÁRIA
A10: ITEM | B10: DESCRIÇÃO | C10: UNID. | D10: QUANT. | E10: PREÇO UNITÁRIO | F10: PREÇO TOTAL
A12: 1.0 | B12: LEVANTAMENTOS GEODÉSICOS | I12: =F14/28.0411 -> 181.42619
A13: 1.1 | B13: Ponto GPS com receptores de dupla freqüência (L1+L2) | C13: unid. | D13: 13 | E13: =CPU!F41 -> 391.33745 | F13: =ROUND(D13*E13,2) -> 5087.39 | G13: =F13/$F$20 -> 0.80914179
A14: Total do item 1.0 | F14: =SUM(F13:F13) -> 5087.39 | G14: =F14/$F$20 -> 0.80914179
A15: 2.0 | B15: DESPESAS CARTORIAIS
A16: 2.1 | B16: Despachante de cartório | C16: unid. | D16: 1 | E16: 1200 | F16: =ROUND(D16*E16,2) -> 1200
A17: Total do item 2.0 | F17: =SUM(F16:F16) -> 1200
B20: TOTAL GERAL | F20: =SUM(F14,F17) -> 6287.39

Sheet CPU
A3: RAFAEL & CIA.
A4: Serviço: EXECUÇÃO DE GEORREFERENCIAMENTO DE IMÓVEL RURAL - Certificação
A5: Unidade: Equipe/dia
A7: 1 | B7: MÃO DE OBRA | C7: UNID. | D7: COEF. | E7: SALÁRIO BASE | F7: VALOR R$
A8: 1.1 | B8: Campo
B9: Topógrafo | C9: mês | D9: =4/30 -> 0.13333333 | E9: 4000 | F9: =D9*E9 -> 533.33333
B10: Aux. de topografia | C10: mês | D10: =2/30 -> 0.066666667 | E10: 1100 | F10: =D10*E10 -> 73.333333
A11: 1.2 | B11: Gabinete
B12: Cadista/Calculista | C12: mês | D12: =4/30 -> 0.13333333 | E12: 2000 | F12: =D12*E12 -> 266.66667
D13: SUBTOTAL | F13: =SUM(F9:F12) -> 873.33333
D14: ENCARGOS SOCIAIS 77,25% | F14: =F13*77.25% -> 674.65
D15: Total do item 1 | F15: =SUM(F13:F14) -> 1547.9833
A17: 2 | B17: LOCOMOÇÃO | C17: UNID. | D17: COEF | E17: CUSTOS (R$) | F17: VALOR (R$)
A18: 2.2 | B18: Equipe de campo
B19: Veículo (Pick Up) | C19: mês | D19: =4/30 -> 0.13333333 | E19: 1500 | F19: =D19*E19 -> 200
B20: Combustível (Gasolina) | C20: L | D20: 91.4 | E20: 3.6 | F20: =D20*E20 -> 329.04
D21: Total do item 2 | F21: =SUM(F18:F20) -> 529.04
A23: 3 | B23: EQUIPAMENTOS E MATERIAIS | C23: UNID. | D23: COEF | E23: CUSTOS (R$) | F23: VALOR (R$)
B24: RTK | C24: mês | D24: =4/30 -> 0.13333333 | E24: 4500 | F24: =D24*E24 -> 600
B25: Marcos de concreto | C25: um | D25: 6 | E25: 15 | F25: =D25*E25 -> 90
D26: Total do item 3 | F26: =SUM(F24:F25) -> 690
A28: 4 | B28: ESTADIA
B29: DIÁRIA | C29: UND | D29: 6 | E29: 120 | F29: =PRODUCT(D29:E29) -> 720
B30: ALIMENTAÇÃO | C30: UND | D30: 12 | E30: 20 | F30: =PRODUCT(D30:E30) -> 240
D31: Total do item 4 | F31: =SUM(F29:F30) -> 960
D34: Total dos item 1,2,3,4 | F34: =SUM(F15,F21,F26,F31) -> 3727.0233
A36: 5 | B36: DESPESAS GERAIS E MATERIAL DE CONSUMO 5% | F36: =5%*F34 -> 186.35117
D37: Total dos item 1,2,3,4,5 | F37: =SUM(F15,F21,F26,F36,F31) -> 3913.3745
A38: 5 | B38: BDI 30% | F38: =30%*F37 -> 1174.0123
A39: 6 | B39: PREÇO MENSAL DA EQUIPE = 1+2+3+4+5 | F39: =SUM(F37+F38) -> 5087.3869
B41: Produtividade diária / ponto | F41: =F39/13 -> 391.33745
G77: =#REF!*#REF! -> #REF!
G78: =#REF!*#REF! -> #REF!
G80: =SUM(G77:G79) -> #REF!
G89: =#REF!*#REF! -> #REF!
G90: =#REF!*#REF! -> #REF!
G91: =#REF!*#REF! -> #REF!
G92: =SUM(G89:G91) -> #REF!
G94: =#REF!*#REF! -> #REF!
G95: =0.8*G94 -> #REF!
...

Sheet Poligonal
A3: EQUIPE A
A4: Serviço: POLIGONAL IIP
A5: Unidade: Equipe/dia
A7: 1 | B7: MÃO DE OBRA | C7: UNID. | D7: COEF. | E7: SALÁRIO BASE | F7: VALOR R$
A8: 1.1 | B8: Campo
B9: Coordenador/campo | C9: mês | D9: 0.15 | E9: =Referencias!$E$13 -> 4702.72 | F9: =D9*E9 -> 705.408
B10: Topógrafo | C10: mês | D10: 1 | E10: =Referencias!$E$14 -> 2207.04 | F10: =D10*E10 -> 2207.04
B11: Aux. de topografia | C11: mês | D11: 2 | E11: =Referencias!$E$15 -> 591.8 | F11: =D11*E11 -> 1183.6
B12: Servente | C12: mês | D12: 1 | E12: =Referencias!$E$16 -> 473.44 | F12: =D12*E12 -> 473.44
A13: 1.2 | B13: Gabinete
B14: Coordenador/Esc | C14: mês | D14: 0.2 | E14: =Referencias!$E$17 -> 2427.74 | F14: =D14*E14 -> 485.548
B15: Cadista/Calculista | C15: mês | D15: 0.25 | E15: =Referencias!$E$18 -> 1260.16 | F15: =D15*E15 -> 315.04
D16: SUBTOTAL | F16: =SUM(F9:F15) -> 5370.076
D17: ENCARGOS SOCIAIS 77,25% | F17: =F16*77.25% -> 4148.3837
D18: Total do item 1 | F18: =SUM(F16:F17) -> 9518.4597
A20: 2 | B20: LOCOMOÇÃO | C20: UNID. | D20: COEF | E20: CUSTOS (R$) | F20: VALOR (R$)
A21: 2.1 | B21: Coordenador de campo
B22: Veículo (Gol) | C22: mês | D22: 0.15 | E22: =Referencias!$E$26 -> 1147.73 | F22: =D22*E22 -> 172.1595
B23: Combustível (Km/L x Km/dia) | C23: L | D23: 31 | E23: =Referencias!$E$28 -> 2.78 | F23: =D23*E23 -> 86.18
A24: 2.2 | B24: Equipe de campo
B25: Veículo (Pick Up) | C25: mês | D25: 1 | E25: =Referencias!$E$27 -> 2817.22 | F25: =D25*E25 -> 2817.22
B26: Combustível (Km/L x Km/dia) | C26: L | D26: 385 | E26: =Referencias!$E$29 -> 2.01 | F26: =D26*E26 -> 773.85
D27: Total do item 2 | F27: =SUM(F22:F26) -> 3849.4095
A29: 3 | B29: EQUIPAMENTOS | C29: UNID. | D29: COEF | E29: CUSTOS (R$) | F29: VALOR (R$)
B30: Estação total classe 3 | C30: mês | D30: 1 | E30: =Referencias!$E$35 -> 2400 | F30: =D30*E30 -> 2400
B31: Micro/Soft/Rádio | C31: mês | D31: 0.3 | E31: =Referencias!$E$47 -> 1200 | F31: =D31*E31 -> 360
D32: Total do item 3 | F32: =SUM(F30:F31) -> 2760
D34: Total dos item 1,2,3 | F34: =SUM(F18+F27+F32) -> 16127.869
A36: 4 | B36: DESPESAS GERAIS E MATERIAL DE CONSUMO 10% | F36: =10%*F34 -> 1612.7869
D37: Total dos item 1,2,3,4 | F37: =SUM(F18+F27+F32+F36) -> 17740.656
A38: 5 | B38: BDI 20% | F38: =20%*F37 -> 3548.1312
A39: 6 | B39: PREÇO MENSAL DA EQUIPE = 1+2+3+4+5 | F39: =SUM(F37+F38) -> 21288.787
A40: 7 | B40: PREÇO UNITÁRIO POR DIA (20 DIAS/MÊS) | F40: =F39/20 -> 1064.4394
A42: Locação de divisas Poligonal classe IIP
C44: UNID. | E44: PRODUTIVIDADE | F44: PREÇO UNITÁRIO
A45: EQUIPE A | C45: Km/dia | E45: 1.7 | F45: =F40/E45 -> 626.1408

Sheet Molumentação
A4: COMPOSIÇÃO DE PREÇOS UNITÁRIOS
A8: CÓDIGO: | B8: SERVIÇO: | H8: UNID.
B10: MARCOS DE CONCRETO p/ Levant. GPS (8 x 12 x 60 cm) | H10: UN
A13: EQUIPAMENTO | B13: MOD. | C13: QUANT. | D13: UTILIZAÇÃO | F13: CUSTO HORÁRIO | H13: PARCIAL
D14: PROD. | E14: IMPROD. | F14: PROD. | G14: IMPROD.
A16: Veículo | B16: Pick-up | C16: 0.4 | D16: 0.2 | E16: 0.8 | F16: ='Hilux CS 2_5 diesel 4x4 102cv'!C51/220 -> 15.546451 | G16: =F16*0.75 -> 11.659838 | H16: =(C16*D16*F16)+(C16*E16*G16) -> 4.9748643
G25: (A) | H25: =SUM(H15:H24) -> 4.9748643
A27: MÃO DE OBRA SUPLEMENTAR | F27: QUANT. | G27: SALÁRIO | H27: PARCIAL
G28: HORA
A29: Servente | F29: 0.6 | G29: =ROUND(Referencias!$E$16*1.7725/176,2) -> 4.77 | H29: =F29*G29 -> 2.862
G34: (B) | H34: =SUM(H29:H33) -> 2.862
A36: MATERIAIS | E36: QUANT. | F36: UNID. | G36: CUSTO | H36: PARCIAL
G37: UNITÁRIO
A38: Marco de Concreto | E38: 1 | F38: UNID. | G38: 31 | H38: =E38*G38 -> 31
A39: Chapa identificadora | E39: 1 | F39: UNID. | G39: 3 | H39: =E39*G39 -> 3
G49: (C) | H49: =SUM(H38:H48) -> 34
G51: (A)+(B)+(C) = (D) | H51: =H25+H34+H49 -> 41.836864
A53: PRODUÇÃO DA EQUIPE | B53: 1 | C53: (E)
E54: CUSTO UNITÁRIO
G55: SEM TRANSPORTE (D)/(E) = (F) | H55: =H51/B53 -> 41.836864
A57: TRANSPORTE | D57: DMT | E57: QUANT. | F57: UNID. | G57: CUSTO | H57: PARCIAL
G58: UNITÁRIO
G62: (G) | H62: =SUM(H59:H61) -> 0
A64: CUSTO DIRETO | G64: (F)+(G) | H64: =H55+H62 -> 41.836864
A65: BDI | G65: 0.2 | H65: =0.2*H64 -> 8.3673729
A66: PREÇO UNITÁRIO | H66: =H64+H65 -> 50.204237
A70: COMPOSIÇÃO DE PREÇOS UNITÁRIOS
A74: CÓDIGO: | B74: SERVIÇO: | H74: UNID.
B76: BARROTES DE MADEIRA (5 x 5 x 50 cm) | H76: UN
A79: EQUIPAMENTO | B79: MOD. | C79: QUANT. | D79: UTILIZAÇÃO | F79: CUSTO HORÁRIO | H79: PARCIAL
D80: PROD. | E80: IMPROD. | F80: PROD. | G80: IMPROD.
A82: Veículo | B82: Pick-up | C82: 0.2 | D82: 0.2 | E82: 0.8 | F82: ='Hilux CS 2_5 diesel 4x4 102cv'!C51/220 -> 15.546451 | G82: =F82*0.75 -> 11.659838 | H82: =(C82*D82*F82)+(C82*E82*G82) -> 2.4874321
G91: (A) | H91: =SUM(H81:H90) -> 2.4874321
A93: MÃO DE OBRA SUPLEMENTAR | F93: QUANT. | G93: SALÁRIO | H93: PARCIAL
G94: HORA
A95: Servente | F95: 0.6 | G95: =ROUND(Referencias!$E$16*1.7725/176,2) -> 4.77 | H95: =F95*G95 -> 2.862
G100: (B) | H100: =SUM(H95:H99) -> 2.862
A102: MATERIAIS | E102: QUANT. | F102: UNID. | G102: CUSTO | H102: PARCIAL
G103: UNITÁRIO
A104: Barrote de madeira (8 x 12 x 60 cm) | E104: 1 | F104: UNID. | G104: =ROUND(1968*0.00125,2) -> 2.46 | H104: =E104*G104 -> 2.46 | I104: Sinapi BA/09 (3997) x 0,00125
...

Sheet BDI
B2: DETALHAMENTO DO BDI - ESTUDOS BÁSICOS
B3: (TOPOGRAFIA, GEOTECNIA, PEDOLOGIA, AEROFOTOGRAMETRIA)
B4: CD: | C4: 100000
B6: Item | C6: Descrição dos Serviços | D6: % | E6: % | F6: Valor | G6: BDI
D7: PV | E7: CD | F7: (R$) | G7: (R$)
B9: 1 | C9: ADMINISTRAÇÃO CENTRAL | E9: 5 | G9: =ROUND(E9*C4/100,2) -> 5000 | I9: a = | J9: 0.0362
B11: 2 | C11: IMPOSTOS E TAXAS | D11: =SUM(D12:D14) -> 8.65 | E11: =SUM(E12:E14) -> 10.38 | G11: =ROUND(SUM(F12:F14),2) -> 10380 | I11: i = | J11: 0.0565
B12: 3.1 | C12: ISS | D12: 5 | E12: =ROUND(D12*(1+($C$23/100)),2) -> 6 | F12: =ROUND(E12*$C$4/100,2) -> 6000
B13: 3.2 | C13: PIS | D13: 0.65 | E13: =ROUND(D13*(1+($C$23/100)),2) -> 0.78 | F13: =ROUND(E13*$C$4/100,2) -> 780
B14: 3.3 | C14: Cofins | D14: 3 | E14: =ROUND(D14*(1+($C$23/100)),2) -> 3.6 | F14: =ROUND(E14*$C$4/100,2) -> 3600
B16: 3 | C16: LUCRO | D16: 8 | E16: 14.62 | F16: =ROUND(E16*$C$4/100,2) -> 14620 | G16: =ROUND(F16,2) -> 14620 | I16: l = | J16: 0.08
B18: BDI (%) | E18: =E9+E11+E16 -> 30 | G18: =G9+G11+#REF!+#REF!+G16 -> #REF! | I18: BDI = ((1+a)/(1-(i+l))-1)*100
E20: PV = | G20: =C4+G18 -> #REF!
B22: BDI = | C22: =((1+E9/100)/(1-(D11/100+D16/100))-1)*100 -> 25.974805 | D22: calculado
B23: BDI = | C23: 20 | D23: adotado

Sheet Enc.Sociais
A1: ENCARGOS SOCIAIS (%)
A3: Taxas de leis sociais e riscos do trabalho (%)
C4: HORISTA | D4: MENSALISTA
A5: A1 | B5: Previdência Social | C5: 20 | D5: 20
A6: A2 | B6: Fundo de Garantia por Tempo de Serviço | C6: 8 | D6: 8
A7: A3 | B7: Salário Educação | C7: 2.5 | D7: 2.5
A8: A4 | B8: Serviço Social da Indústira (Sesi) | C8: 1.5 | D8: 1.5
A9: A5 | B9: Serviço Nacional de Aprendizagem Industrial (Senai) | C9: 1 | D9: 1
A10: A6 | B10: Serviço de Apoio a Pequena e Média Empresa (Sebrae) | C10: 0.6 | D10: 0.6
A11: A7 | B11: Instituto Nacional de Colonização e Reforma Agrária (Incra) | C11: 0.2 | D11: 0.2
A12: A8 | B12: Seguro contra os acidentes de trabalho (INSS) | C12: 3 | D12: 3
A13: A9 | B13: Seconci (Serviço Social da Indústria da Construção e do Mobiliário) | C13: 0 | D13: 0
A15: A | B15: Total dos Encargos Sociais | C15: =SUM(C5:C13) -> 36.8 | D15: =ROUND(SUM(D5:D13),2) -> 36.8
A17: B1 | B17: Repouso Semanal e feriados | C17: 22.9 | D17: -
A18: B2 | B18: Auxílio-enfermidade | C18: 0.79 | D18: -
A19: B3 | B19: Licença-paternidade | C19: 0.34 | D19: -
A20: B4 | B20: 13° salário | C20: 10.57 | D20: 8.22
A21: B5 | B21: Dias de chuva / faltas justificadas na obra / outras dificuldades | C21: 4.57 | D21: -
A23: B | B23: Total dos Encargos Sociais que recebem as incidências de A | C23: =SUM(C17:C21) -> 39.17 | D23: =ROUND(SUM(D17:D21),2) -> 8.22
A25: C1 | B25: Depósito por despedida injusta: 50% sobre (A2 + (A2 x B)) | C25: =ROUND(((C6/100)+((C6/100)*(C23/100)))/2*100,2) -> 5.57 | D25: =((D6/100)+((D6/100)*(D23/100)))/2*100 -> 4.3288
A26: C2 | B26: Férias (indenizadas) | C26: 14.06 | D26: 10.93
A27: C3 | B27: Aviso-prévio (indenizado) – decreto 6.727/2009 | C27: 13.12 | D27: 10.2
A29: C | B29: Total dos Encargos Sociais que não recebem as incidências de A | C29: =SUM(C25:C27) -> 32.75 | D29: =ROUND(SUM(D25:D27),2) -> 25.46
A31: D1 | B31: Reincidência de A sobre B | C31: =ROUND((C15/100*C23/100)*100,2) -> 14.41 | D31: =ROUND((D15/100*D23/100)*100,2) -> 3.02
A32: D2 | B32: Reincidência de A (exceto Seconci) sobre C3 | C32: =ROUND(((C15-C13)*C27)/100,2) -> 4.83 | D32: =ROUND(((D15-D13)*D27)/100,2) -> 3.75
A34: D | B34: Total da Reincidências | C34: =SUM(C31:C32) -> 19.24 | D34: =ROUND(SUM(D31:D32),2) -> 6.77
B36: T O T A L | C36: =C34+C29+C23+C15 -> 127.96 | D36: =ROUND(D34+D29+D23+D15,2) -> 77.25

Sheet Referencias
A1: TABELA DE PREÇOS UNITÁRIOS DE REFERÊNCIA TOPOGRAFIA
A3: SERVIÇOS | D3: Unid. | E3: EQUIPE | F3: PREÇO EQUIPE / DIA (R$) | G3: PRODUTIVIDADE / DIA | H3: PREÇO UNIT. (R$) | K3: REVISTA
A4: 17 | B4: Pontos GPS, com receptores de dupla frequencia (L1/L2) | D4: Unid. | E4: L | F4: =CPU!#REF! -> #REF! | G4: =CPU!#REF! -> #REF! | H4: =F4/G4 -> #REF!
A5: 18 | B5: Pontos GPS, com receptores de uma frequencia (L1) | D5: Unid. | E5: L | F5: =F4 -> #REF! | G5: 12 | H5: =F5/G5 -> #REF!
A7: DATA-BASE: MAR/2009
A9: TABELA DE INSUMOS
A10: Discriminação | C10: Un | E10: Custo
A12: Mão de Obra
A13: Coordenador/campo | C13: mês | E13: 4702.72 | F13: P3 | G13: atualizado out/09
A14: Topógrafo | C14: mês | E14: 2207.04 | F14: IC | G14: atualizado out/09 | H14: COLUNA 39
A15: Aux. Topografia | C15: mês | E15: 591.8 | F15: SERVENTE + 25% | G15: atualizado out/09 | H15: Io (junho/05) | I15: 135.571
A16: Servente | C16: mês | E16: 473.44 | F16: T4 | G16: atualizado out/09 | H16: I1 (maio/07) | I16: 145.225
A17: Coordenador/Esc | C17: mês | E17: =ROUND(E14*1.1,2) -> 2427.74 | F17: TOPOGRÁFO + 10% | G17: atualizado out/09 | H17: I | I17: =I16/I15 -> 1.0712099
A18: Cadista/calculista | C18: mês | E18: 1260.16 | F18: IC (encarreg. de forma) | G18: atualizado out/09
A19: Encarregado | C19: mês | E19: =ROUND(E14*1.4,2) -> 3089.86 | F19: TOPOGRÁFO + 40% | G19: atualizado out/09
A20: Técnico Detectorista | C20: mês | E20: =E14 -> 2207.04 | F20: (*) = TOPOGRÁFO | G20: atualizado out/09
A21: Ajudante | C21: mês | E21: 473.44 | F21: T4 | G21: atualizado out/09
A22: Barqueiro | C22: mês | E22: 709.23 | F22: T3 | G22: atualizado out/09
A23: Operador ecobatimetro | C23: mês | E23: 1981.76 | F23: T1 | G23: atualizado out/09
A24: Equipamentos/Insumos
A26: Veículo (Gol) | C26: mês | E26: 1147.73 | F26: s/ combust | G26: atualizado out/09
A27: Veículo (Pick Up) | C27: mês | E27: 2817.22 | F27: s/ combust | G27: atualizado out/09
A28: Combustivel Gasolina | C28: l | E28: 2.78 | G28: atualizado out/09
A29: Combustivel Diesel | C29: l | E29: 2.01 | G29: atualizado out/09
A31: Equipamentos - de topografia | D31: Precisão
A33: Estação Total - Classe 1 | C33: mês | D33: 7" | E33: 1400 | F33: atualizado nov/09 | G33: Teo
A34: Estação Total - Classe 2 | C34: mês | D34: 5" | E34: 1500 | F34: atualizado nov/09 | G34: Teo
A35: Estação Total - Classe 3 | C35: mês | D35: 3" | E35: 2400 | F35: Estimado à partir do preço de venda em comparação com o valor da locação da estação de 7"
A36: Teodolito Classe 1 | C36: mês | D36: 1" | E36: 780
A37: Teodolito Classe 2 | C37: mês | D37: 6" | E37: 570
A38: Teodolito Classe 3 | C38: mês | D38: 60" | E38: 480
A39: Miras Invar | C39: mês | E39: 150
A41: Nivel Classe 2 | C41: mês | D41: 2,5mm/km | E41: 270
A42: Nivel Classe 3 NA2 | C42: mês | D42: 2mm/km | E42: 315
A43: Nivel Classe 4 N3 | C43: mês | D43: 0,2mm/km | E43: 990
A45: GPS (Geodesico L1+L2) | C45: mês | E45: 4990 | G45: atualizado out/09
A47: Micro/Soft/Radio | C47: mês | E47: 1200
A48: Micro/Soft | C48: mês | E48: 780
A50: Distanciômetro eletrônico classe 3 | C50: mês | D50: 2000m | E50: 890
A51: Detector de metais | C51: mês | E51: 180
...

Sheet Gol 1_0 flex
D5: Novo Gol G5 1.0 flex (72 CV)
C7: A | D7: Depreciação mensal do equipamento
C8: A1 | D8: Preço de Aquisição | E8: ='[1]Valores de Aquisição'!$C$14 -> 31350
C9: A2 | D9: Tempo previsto de vida útil (meses) | E9: 36
C10: A3 | D10: Previsão de recup. Na venda do bem usado | E10: 0.4
C11: A4 | D11: Custo mensal [A1-(A3xA1)]/A2 | E11: =(E8-(E10*E8))/E9 -> 522.5
C13: B | D13: Juros pelo Capital empregado
C14: B1 | D14: Taxa mensal de Juros | E14: 0.05
C15: B2 | D15: Juros s/depreciação/aluguel (B1xA4) | E15: =E14*E11 -> 26.125
C17: C | D17: Conservação e manutenção
C18: C1 | D18: Taxa de gastos s/a deprec. Inc. seguros (%) | E18: 1
C19: C2 | D19: Incidência mensal (C1xA4) | E19: =E18*E11 -> 522.5
C21: D | D21: Combustível
C22: D1 | D22: Média mensal de quilômetro por veículo | E22: 3000
C23: D2 | D23: Preço do litro de combustível | E23: ='[1]Valores de Aquisição'!$C$2 -> 2.78
C24: D3 | D24: Quilômetros rodados com um litro combustivel | E24: 10
C25: D4 | D25: Combustivel (D1/D3)*D2 | E25: =(E22/E24)*E23 -> 834
C27: E | D27: Lubrificantes
C28: E1 | D28: Quilometragem do Contrato | E28: =E22*12 -> 36000
C29: E2 | D29: Franquia por troca de óleo (km) | E29: 5000
C30: E3 | D30: Preço do litro de óleo | E30: 10
C31: E4 | D31: Quantidade de litros de óleo por troca | E31: 3.5
C32: E5 | D32: Quantidade de dias do Contrato | E32: 365
C33: E6 | D33: Lubrificantes E = (E1*E3*E4*30)/E2*E5 | E33: =(E28*E30*E31*30)/(E29*E32) -> 20.712329
C35: F | D35: Pneus
C36: F1 | D36: Quilometragem do Contrato | E36: =E22*12 -> 36000
C37: F2 | D37: Vida do Pneu em quilômetros | E37: 45000
C38: F3 | D38: Quantidade de pneus | E38: 5
C39: F4 | D39: Preço do Pneu | E39: 170
C40: F5 | D40: Quantidade de dias do contrato | E40: 365
C41: F6 | D41: Pneus = (F1*F3*F4*30)/(F2*F5) | E41: =(E36*E38*E39*30)/(E37*E40) -> 55.890411
C46: G | D46: Motorista
C47: G1 | D47: Salário com encargos sociais | E47: =4.2*176*1.7725 -> 1310.232
C49: H | D49: Custo Mensal
D50: Sem Motorista | E50: =E11+E15+E19+E25+E33+E41 -> 1981.7277
D51: Com Motorista | E51: =E11+E15+E19+E25+E33+E41+E47 -> 3291.9597
C53: I | D53: Custo Direto p/ km Rodado
D54: Sem Motorista | E54: =E50/E22 -> 0.66057591
D55: Com Motorista | E55: =E51/E22 -> 1.0973199
C57: J | D57: Preço cobrado pela empresa
...

Sheet Hilux CS 2_5 diesel 4x4 102cv
B5: Hilux CS 2.5 diesel 4x4 102cv
A7: A | B7: Depreciação mensal do equipamento
A8: A1 | B8: Preço de Aquisição | C8: ='[1]Valores de Aquisição'!$C$23 -> 78000
A9: A2 | B9: Tempo previsto de vida útil (meses) | C9: 36
A10: A3 | B10: Previsão de recup. Na venda do bem usado | C10: 0.4
A11: A4 | B11: Custo mensal [A1-(A3xA1)]/A2 | C11: =(C8-(C10*C8))/C9 -> 1300
A13: B | B13: Juros pelo Capital empregado
A14: B1 | B14: Taxa mensal de Juros | C14: 0.05
A15: B2 | B15: Juros s/depreciação/aluguel (B1xA4) | C15: =C14*C11 -> 65
A17: C | B17: Conservação e manutenção
A18: C1 | B18: Taxa de gastos s/a deprec. Inc. seguros (%) | C18: 1
A19: C2 | B19: Incidência mensal (C1xA4) | C19: =C18*C11 -> 1300
A21: D | B21: Combustível
A22: D1 | B22: Média mensal de quilômetro por veículo | C22: 3000
A23: D2 | B23: Preço do litro de combustível | C23: ='[1]Valores de Aquisição'!C4 -> 2.01
A24: D3 | B24: Quilômetros rodados com um litro combustivel | C24: 10
A25: D4 | B25: Combustivel (D1/D3)*D2 | C25: =(C22/C24)*C23 -> 603
A27: E | B27: Lubrificantes
A28: E1 | B28: Quilometragem do Contrato | C28: =C22*12 -> 36000
A29: E2 | B29: Franquia por troca de óleo (km) | C29: 5000
A30: E3 | B30: Preço do litro de óleo | C30: 10
A31: E4 | B31: Quantidade de litros de óleo por troca | C31: 3.5
A32: E5 | B32: Quantidade de dias do Contrato | C32: 365
A33: E6 | B33: Lubrificantes E = (E1*E3*E4*30)/E2*E5 | C33: =(C28*C30*C31*30)/(C29*C32) -> 20.712329
A35: F | B35: Pneus
A36: F1 | B36: Quilometragem do Contrato | C36: =C22*12 -> 36000
A37: F2 | B37: Vida do Pneu em quilômetros | C37: 45000
A38: F3 | B38: Quantidade de pneus | C38: 5
A39: F4 | B39: Preço do Pneu | C39: 400
A40: F5 | B40: Quantidade de dias do contrato | C40: 365
A41: F6 | B41: Pneus = (F1*F3*F4*30)/(F2*F5) | C41: =(C36*C38*C39*30)/(C37*C40) -> 131.50685
A47: G | B47: Motorista
A48: G1 | B48: Salário com encargos sociais | C48: =4.2*176*1.7725 -> 1310.232
A50: H | B50: Custo Mensal
B51: Sem Motorista | C51: =C11+C15+C19+C25+C33+C41 -> 3420.2192
B52: Com Motorista | C52: =C11+C15+C19+C25+C33+C41+C48 -> 4730.4512
A54: I | B54: Custo Direto p/ km Rodado
B55: Sem Motorista | C55: =C51/C22 -> 1.1400731
B56: Com Motorista | C56: =C52/C22 -> 1.5768171
A58: J | B58: Preço cobrado pela empresa
...

Sheet Plan1
